<?xml version="1.0" ?>
<robot name="Servo_clone" xmlns:xacro="http://www.ros.org/wiki/xacro">

<xacro:include filename="$(find Servo_clone_description)/urdf/materials.xacro" />
<xacro:include filename="$(find Servo_clone_description)/urdf/Servo_clone.trans" />
<xacro:include filename="$(find Servo_clone_description)/urdf/Servo_clone.gazebo" />
<xacro:include filename="$(find ros2_control_demo_example_1)/ros2_control/servo_arm.ros2_control.xacro" />

<link name="base_link">
  <inertial>
    <origin xyz="-0.0003733261171936679 -1.415969839225099e-10 -0.003749778735520101" rpy="0 0 0"/>
    <mass value="0.05514475420323322"/>
    <inertia ixx="4e-06" iyy="6e-06" izz="3e-06" ixy="-0.0" iyz="0.0" ixz="0.0"/>
  </inertial>
  <visual>
    <origin xyz="0 0 0" rpy="0 0 0"/>
    <geometry>
      <mesh filename="file://$(find Servo_clone_description)/meshes/base_link.stl" scale="0.001 0.001 0.001"/>
    </geometry>
    <material name="silver"/>
  </visual>
  <collision>
    <origin xyz="0 0 0" rpy="0 0 0"/>
    <geometry>
      <mesh filename="file://$(find Servo_clone_description)/meshes/base_link.stl" scale="0.001 0.001 0.001"/>
    </geometry>
  </collision>
</link>

<link name="horn_1">
  <inertial>
    <origin xyz="8.352693536828326e-16 -8.054779743942258e-18 0.000837172855025211" rpy="0 0 0"/>
    <mass value="0.0022458903814511905"/>
    <inertia ixx="0.0" iyy="0.0" izz="0.0" ixy="-0.0" iyz="-0.0" ixz="-0.0"/>
  </inertial>
  <visual>
    <origin xyz="0.00535 -0.0 -0.0136" rpy="0 0 0"/>
    <geometry>
      <mesh filename="file://$(find Servo_clone_description)/meshes/horn_1.stl" scale="0.001 0.001 0.001"/>
    </geometry>
    <material name="silver"/>
  </visual>
  <collision>
    <origin xyz="0.00535 -0.0 -0.0136" rpy="0 0 0"/>
    <geometry>
      <mesh filename="file://$(find Servo_clone_description)/meshes/horn_1.stl" scale="0.001 0.001 0.001"/>
    </geometry>
  </collision>
</link>

<link name="arm_base_1">
  <inertial>
    <origin xyz="-0.0187517959656261 -1.796348326727161e-17 -0.0038637379533287297" rpy="0 0 0"/>
    <mass value="0.16304743822991946"/>
    <inertia ixx="6e-05" iyy="6.9e-05" izz="0.000107" ixy="0.0" iyz="-0.0" ixz="0.0"/>
  </inertial>
  <visual>
    <origin xyz="-0.0139 0.0 -0.0" rpy="0 0 0"/>
    <geometry>
      <mesh filename="file://$(find Servo_clone_description)/meshes/arm_base_1.stl" scale="0.001 0.001 0.001"/>
    </geometry>
    <material name="silver"/>
  </visual>
  <collision>
    <origin xyz="-0.0139 0.0 -0.0" rpy="0 0 0"/>
    <geometry>
      <mesh filename="file://$(find Servo_clone_description)/meshes/arm_base_1.stl" scale="0.001 0.001 0.001"/>
    </geometry>
  </collision>
</link>

<joint name="Revolute_1" type="revolute">
  <origin xyz="-0.00535 0.0 0.0136" rpy="0 0 0"/>
  <parent link="base_link"/>
  <child link="horn_1"/>
  <axis xyz="0.0 0.0 1.0"/>
  <limit upper="1.570796" lower="-1.570796" effort="100" velocity="100"/>
</joint>

<joint name="Rigid_4" type="fixed">
  <origin xyz="0.0139 0.0 0.0" rpy="0 0 0"/>
  <parent link="base_link"/>
  <child link="arm_base_1"/>
</joint>

</robot>
